<?xml version="1.0" encoding="utf-8"?>
<!-- This URDF was automatically created by SolidWorks to URDF Exporter! Originally created by Stephen Brawner (brawner@gmail.com) 
     Commit Version: 1.6.0-1-g15f4949  Build Version: 1.6.7594.29634
     For more information, please see http://wiki.ros.org/sw_urdf_exporter -->
<robot
  name="mori3">
  <link
    name="base_link">
    <inertial>
      <origin
        xyz="0 -5.5511E-17 -0.005"
        rpy="0 0 0" />
      <mass
        value="6.0795" />
      <inertia
        ixx="0.022849"
        ixy="-1.3133E-17"
        ixz="-3.31E-20"
        iyy="0.022849"
        iyz="8.24E-20"
        izz="0.045596" />
    </inertial>
    <visual>
      <origin
        xyz="0 0 0"
        rpy="0 0 0" />
      <geometry>
        <mesh
          filename="/home/liyiming/legged_gym/resources/robots/Mori1/meshes/base_link.STL" />
      </geometry>
      <material
        name="">
        <color
          rgba="0.52941 0.54902 0.54902 1" />
      </material>
    </visual>
    <collision>
      <origin
        xyz="0 0 0"
        rpy="0 0 0" />
      <geometry>
        <mesh
          filename="/home/liyiming/legged_gym/resources/robots/Mori1/meshes/base_link.STL" />
      </geometry>
    </collision>
  </link>
  <link
    name="LR_hip">
    <inertial>
      <origin
        xyz="-0.0866025403784438 0 -0.15"
        rpy="0 0 0" />
      <mass
        value="3.03974916728338" />
      <inertia
        ixx="0.0114243906203734"
        ixy="-9.35755222096044E-20"
        ixz="-5.20417042793042E-18"
        iyy="0.0227981187546254"
        iyz="-8.23594196495199E-20"
        izz="0.0114243906203734" />
    </inertial>
    <visual>
      <origin
        xyz="0 0 0"
        rpy="0 0 0" />
      <geometry>
        <mesh
          filename="/home/liyiming/legged_gym/resources/robots/Mori1/meshes/LR_hip.STL" />
      </geometry>
      <material
        name="">
        <color
          rgba="0.529411764705882 0.549019607843137 0.549019607843137 1" />
      </material>
    </visual>
    <collision>
      <origin
        xyz="0 0 0"
        rpy="0 0 0" />
      <geometry>
        <mesh
          filename="/home/liyiming/legged_gym/resources/robots/Mori1/meshes/LR_hip.STL" />
      </geometry>
    </collision>
  </link>
  <joint
    name="LR_hip_joint"
    type="revolute">
    <origin
      xyz="0 0.25981 -0.005"
      rpy="-1.5708 0 -0.5236" />
    <parent
      link="base_link" />
    <child
      link="LR_hip" />
    <axis
      xyz="0 0 -1" />
    <limit
      lower="-0.792"
      upper="2.356"
      effort="160"
      velocity="52.4" />
  </joint>
  <link
    name="LR_calf">
    <inertial>
      <origin
        xyz="1.11022302462516E-16 0.0866025403784439 -0.15"
        rpy="0 0 0" />
      <mass
        value="3.03974916728338" />
      <inertia
        ixx="0.0227981187546253"
        ixy="8.89347180319382E-19"
        ixz="8.67361737988404E-19"
        iyy="0.0114243906203733"
        iyz="1.80658906474455E-18"
        izz="0.0114243906203734" />
    </inertial>
    <visual>
      <origin
        xyz="0 0 0"
        rpy="0 0 0" />
      <geometry>
        <mesh
          filename="/home/liyiming/legged_gym/resources/robots/Mori1/meshes/LR_calf.STL" />
      </geometry>
      <material
        name="">
        <color
          rgba="0.529411764705882 0.549019607843137 0.549019607843137 1" />
      </material>
    </visual>
    <collision>
      <origin
        xyz="0 0 0"
        rpy="0 0 0" />
      <geometry>
        <mesh
          filename="/home/liyiming/legged_gym/resources/robots/Mori1/meshes/LR_calf.STL" />
      </geometry>
    </collision>
  </link>
  <joint
    name="LR_calf_joint"
    type="revolute">
    <origin
      xyz="-0.25981 0 -0.15"
      rpy="0 -1.0472 0" />
    <parent
      link="LR_hip" />
    <child
      link="LR_calf" />
    <axis
      xyz="0 0 1" />
    <limit
      lower="-2.112"
      upper="2.112"
      effort="160"
      velocity="28.6" />
  </joint>
  <link
    name="LR_foot">
    <inertial>
      <origin
        xyz="0 0 0"
        rpy="0 0 0" />
      <mass
        value="0.00418879020478639" />
      <inertia
        ixx="1.67551608191456E-07"
        ixy="0"
        ixz="0"
        iyy="1.67551608191456E-07"
        iyz="0"
        izz="1.67551608191456E-07" />
    </inertial>
    <visual>
      <origin
        xyz="0 0 0"
        rpy="0 0 0" />
      <geometry>
        <mesh
          filename="/home/liyiming/legged_gym/resources/robots/Mori1/meshes/LR_foot.STL" />
      </geometry>
      <material
        name="">
        <color
          rgba="0.298039215686275 0.298039215686275 0.298039215686275 1" />
      </material>
    </visual>
    <collision>
      <origin
        xyz="0 0 0"
        rpy="0 0 0" />
      <geometry>
        <mesh
          filename="/home/liyiming/legged_gym/resources/robots/Mori1/meshes/LR_foot.STL" />
      </geometry>
    </collision>
  </link>
  <joint
    name="LR_foot_joint"
    type="fixed">
    <origin
      xyz="0 0.25981 -0.15"
      rpy="1.5708 0.5236 0" />
    <parent
      link="LR_calf" />
    <child
      link="LR_foot" />
    <axis
      xyz="0 0 0" />
  </joint>
  <link
    name="RR_hip">
    <inertial>
      <origin
        xyz="-0.0866025403784439 1.11022302462516E-16 0.15"
        rpy="0 0 0" />
      <mass
        value="3.03974916728338" />
      <inertia
        ixx="0.0114243906203734"
        ixy="-3.39657632964252E-20"
        ixz="-3.03576608295941E-18"
        iyy="0.0227981187546253"
        iyz="1.40707673508369E-20"
        izz="0.0114243906203734" />
    </inertial>
    <visual>
      <origin
        xyz="0 0 0"
        rpy="0 0 0" />
      <geometry>
        <mesh
          filename="/home/liyiming/legged_gym/resources/robots/Mori1/meshes/RR_hip.STL" />
      </geometry>
      <material
        name="">
        <color
          rgba="0.529411764705882 0.549019607843137 0.549019607843137 1" />
      </material>
    </visual>
    <collision>
      <origin
        xyz="0 0 0"
        rpy="0 0 0" />
      <geometry>
        <mesh
          filename="/home/liyiming/legged_gym/resources/robots/Mori1/meshes/RR_hip.STL" />
      </geometry>
    </collision>
  </link>
  <joint
    name="RR_hip_joint"
    type="revolute">
    <origin
      xyz="0 -0.25981 -0.005"
      rpy="-1.5708 0 0.5236" />
    <parent
      link="base_link" />
    <child
      link="RR_hip" />
    <axis
      xyz="0 0 1" />
    <limit
      lower="-0.792"
      upper="2.356"
      effort="160"
      velocity="52.4" />
  </joint>
  <link
    name="RR_calf">
    <inertial>
      <origin
        xyz="-2.77555756156289E-17 0.0866025403784436 0.15"
        rpy="0 0 0" />
      <mass
        value="3.03974916728338" />
      <inertia
        ixx="0.0227981187546253"
        ixy="6.35853473661919E-19"
        ixz="-2.16840434497101E-18"
        iyy="0.0114243906203733"
        iyz="1.27528336817992E-18"
        izz="0.0114243906203734" />
    </inertial>
    <visual>
      <origin
        xyz="0 0 0"
        rpy="0 0 0" />
      <geometry>
        <mesh
          filename="/home/liyiming/legged_gym/resources/robots/Mori1/meshes/RR_calf.STL" />
      </geometry>
      <material
        name="">
        <color
          rgba="0.529411764705882 0.549019607843137 0.549019607843137 1" />
      </material>
    </visual>
    <collision>
      <origin
        xyz="0 0 0"
        rpy="0 0 0" />
      <geometry>
        <mesh
          filename="/home/liyiming/legged_gym/resources/robots/Mori1/meshes/RR_calf.STL" />
      </geometry>
    </collision>
  </link>
  <joint
    name="RR_calf_joint"
    type="revolute">
    <origin
      xyz="-0.25981 0 0.15"
      rpy="0 1.0472 0" />
    <parent
      link="RR_hip" />
    <child
      link="RR_calf" />
    <axis
      xyz="0 0 1" />
    <limit
      lower="-2.112"
      upper="2.112"
      effort="160"
      velocity="28.6" />
  </joint>
  <link
    name="RR_foot">
    <inertial>
      <origin
        xyz="0 0 0"
        rpy="0 0 0" />
      <mass
        value="0.00418879020478639" />
      <inertia
        ixx="1.67551608191456E-07"
        ixy="0"
        ixz="0"
        iyy="1.67551608191456E-07"
        iyz="0"
        izz="1.67551608191456E-07" />
    </inertial>
    <visual>
      <origin
        xyz="0 0 0"
        rpy="0 0 0" />
      <geometry>
        <mesh
          filename="/home/liyiming/legged_gym/resources/robots/Mori1/meshes/RR_foot.STL" />
      </geometry>
      <material
        name="">
        <color
          rgba="0.298039215686275 0.298039215686275 0.298039215686275 1" />
      </material>
    </visual>
    <collision>
      <origin
        xyz="0 0 0"
        rpy="0 0 0" />
      <geometry>
        <mesh
          filename="/home/liyiming/legged_gym/resources/robots/Mori1/meshes/RR_foot.STL" />
      </geometry>
    </collision>
  </link>
  <joint
    name="RR_foot_joint"
    type="fixed">
    <origin
      xyz="0 0.259807621135331 0.15"
      rpy="1.5707963267949 -0.523598775598299 0" />
    <parent
      link="RR_calf" />
    <child
      link="RR_foot" />
    <axis
      xyz="0 0 0" />
  </joint>
  <link
    name="LF_hip">
    <inertial>
      <origin
        xyz="0.0866025403784438 -5.55111512312578E-17 0.15"
        rpy="0 0 0" />
      <mass
        value="3.03974916728338" />
      <inertia
        ixx="0.0114243906203733"
        ixy="-1.09469372173044E-19"
        ixz="-7.37257477290143E-18"
        iyy="0.0227981187546253"
        iyz="4.76632259869572E-20"
        izz="0.0114243906203734" />
    </inertial>
    <visual>
      <origin
        xyz="0 0 0"
        rpy="0 0 0" />
      <geometry>
        <mesh
          filename="/home/liyiming/legged_gym/resources/robots/Mori1/meshes/LF_hip.STL" />
      </geometry>
      <material
        name="">
        <color
          rgba="0.529411764705882 0.549019607843137 0.549019607843137 1" />
      </material>
    </visual>
    <collision>
      <origin
        xyz="0 0 0"
        rpy="0 0 0" />
      <geometry>
        <mesh
          filename="/home/liyiming/legged_gym/resources/robots/Mori1/meshes/LF_hip.STL" />
      </geometry>
    </collision>
  </link>
  <joint
    name="LF_hip_joint"
    type="revolute">
    <origin
      xyz="0 0.25981 -0.005"
      rpy="1.5708 0 0.5236" />
    <parent
      link="base_link" />
    <child
      link="LF_hip" />
    <axis
      xyz="0 0 -1" />
    <limit
      lower="-0.792"
      upper="2.356"
      effort="160"
      velocity="52.4" />
  </joint>
  <link
    name="LF_calf">
    <inertial>
      <origin
        xyz="5.55111512312578E-17 0.0866025403784437 -0.15"
        rpy="0 0 0" />
      <mass
        value="3.03974916728338" />
      <inertia
        ixx="0.0227981187546253"
        ixy="-2.99302413577147E-18"
        ixz="-2.16840434497101E-18"
        iyy="0.0114243906203734"
        iyz="-9.43748151551319E-18"
        izz="0.0114243906203734" />
    </inertial>
    <visual>
      <origin
        xyz="0 0 0"
        rpy="0 0 0" />
      <geometry>
        <mesh
          filename="/home/liyiming/legged_gym/resources/robots/Mori1/meshes/LF_calf.STL" />
      </geometry>
      <material
        name="">
        <color
          rgba="0.529411764705882 0.549019607843137 0.549019607843137 1" />
      </material>
    </visual>
    <collision>
      <origin
        xyz="0 0 0"
        rpy="0 0 0" />
      <geometry>
        <mesh
          filename="/home/liyiming/legged_gym/resources/robots/Mori1/meshes/LF_calf.STL" />
      </geometry>
    </collision>
  </link>
  <joint
    name="LF_calf_joint"
    type="revolute">
    <origin
      xyz="0.25981 0 0.15"
      rpy="-3.1416 -1.0472 0" />
    <parent
      link="LF_hip" />
    <child
      link="LF_calf" />
    <axis
      xyz="0 0 -1" />
    <limit
      lower="-2.112"
      upper="2.112"
      effort="160"
      velocity="28.6" />
  </joint>
  <link
    name="LF_foot">
    <inertial>
      <origin
        xyz="0 0 0"
        rpy="0 0 0" />
      <mass
        value="0.00418879020478639" />
      <inertia
        ixx="1.67551608191456E-07"
        ixy="0"
        ixz="0"
        iyy="1.67551608191456E-07"
        iyz="0"
        izz="1.67551608191456E-07" />
    </inertial>
    <visual>
      <origin
        xyz="0 0 0"
        rpy="0 0 0" />
      <geometry>
        <mesh
          filename="/home/liyiming/legged_gym/resources/robots/Mori1/meshes/LF_foot.STL" />
      </geometry>
      <material
        name="">
        <color
          rgba="0.298039215686275 0.298039215686275 0.298039215686275 1" />
      </material>
    </visual>
    <collision>
      <origin
        xyz="0 0 0"
        rpy="0 0 0" />
      <geometry>
        <mesh
          filename="/home/liyiming/legged_gym/resources/robots/Mori1/meshes/LF_foot.STL" />
      </geometry>
    </collision>
  </link>
  <joint
    name="LF_foot_joint"
    type="fixed">
    <origin
      xyz="0 0.259807621135331 -0.15"
      rpy="1.5707963267949 -0.523598775598299 0" />
    <parent
      link="LF_calf" />
    <child
      link="LF_foot" />
    <axis
      xyz="0 0 0" />
  </joint>
  <link
    name="RF_hip">
    <inertial>
      <origin
        xyz="0.0866025403784439 0 -0.15"
        rpy="0 0 0" />
      <mass
        value="3.03974916728338" />
      <inertia
        ixx="0.0114243906203734"
        ixy="1.79933166105513E-20"
        ixz="2.60208521396521E-18"
        iyy="0.0227981187546253"
        iyz="-1.59278214203013E-20"
        izz="0.0114243906203733" />
    </inertial>
    <visual>
      <origin
        xyz="0 0 0"
        rpy="0 0 0" />
      <geometry>
        <mesh
          filename="/home/liyiming/legged_gym/resources/robots/Mori1/meshes/RF_hip.STL" />
      </geometry>
      <material
        name="">
        <color
          rgba="0.529411764705882 0.549019607843137 0.549019607843137 1" />
      </material>
    </visual>
    <collision>
      <origin
        xyz="0 0 0"
        rpy="0 0 0" />
      <geometry>
        <mesh
          filename="/home/liyiming/legged_gym/resources/robots/Mori1/meshes/RF_hip.STL" />
      </geometry>
    </collision>
  </link>
  <joint
    name="RF_hip_joint"
    type="revolute">
    <origin
      xyz="0 -0.25981 -0.005"
      rpy="1.5708 0 -0.5236" />
    <parent
      link="base_link" />
    <child
      link="RF_hip" />
    <axis
      xyz="0 0 1" />
    <limit
      lower="-0.792"
      upper="2.356"
      effort="160"
      velocity="52.4" />
  </joint>
  <link
    name="RF_calf">
    <inertial>
      <origin
        xyz="-3.81639164714898E-17 -0.0866025403784439 -0.15"
        rpy="0 0 0" />
      <mass
        value="3.03974916728337" />
      <inertia
        ixx="0.0227981187546253"
        ixy="3.88212808392291E-18"
        ixz="-3.03576608295941E-18"
        iyy="0.0114243906203733"
        iyz="-1.87197005712458E-18"
        izz="0.0114243906203733" />
    </inertial>
    <visual>
      <origin
        xyz="0 0 0"
        rpy="0 0 0" />
      <geometry>
        <mesh
          filename="/home/liyiming/legged_gym/resources/robots/Mori1/meshes/RF_calf.STL" />
      </geometry>
      <material
        name="">
        <color
          rgba="0.529411764705882 0.549019607843137 0.549019607843137 1" />
      </material>
    </visual>
    <collision>
      <origin
        xyz="0 0 0"
        rpy="0 0 0" />
      <geometry>
        <mesh
          filename="/home/liyiming/legged_gym/resources/robots/Mori1/meshes/RF_calf.STL" />
      </geometry>
    </collision>
  </link>
  <joint
    name="RF_calf_joint"
    type="revolute">
    <origin
      xyz="0.25981 0 -0.15"
      rpy="0 1.0472 0" />
    <parent
      link="RF_hip" />
    <child
      link="RF_calf" />
    <axis
      xyz="0 0 1" />
    <limit
      lower="-2.112"
      upper="2.112"
      effort="160"
      velocity="28.6" />
  </joint>
  <link
    name="RF_foot">
    <inertial>
      <origin
        xyz="0 0 0"
        rpy="0 0 0" />
      <mass
        value="0.00418879020478639" />
      <inertia
        ixx="1.67551608191456E-07"
        ixy="0"
        ixz="0"
        iyy="1.67551608191456E-07"
        iyz="0"
        izz="1.67551608191456E-07" />
    </inertial>
    <visual>
      <origin
        xyz="0 0 0"
        rpy="0 0 0" />
      <geometry>
        <mesh
          filename="/home/liyiming/legged_gym/resources/robots/Mori1/meshes/RF_foot.STL" />
      </geometry>
      <material
        name="">
        <color
          rgba="0.298039215686275 0.298039215686275 0.298039215686275 1" />
      </material>
    </visual>
    <collision>
      <origin
        xyz="0 0 0"
        rpy="0 0 0" />
      <geometry>
        <mesh
          filename="/home/liyiming/legged_gym/resources/robots/Mori1/meshes/RF_foot.STL" />
      </geometry>
    </collision>
  </link>
  <joint
    name="RF_foot_joint"
    type="fixed">
    <origin
      xyz="0 -0.25981 -0.15"
      rpy="-1.5708 -0.5236 0" />
    <parent
      link="RF_calf" />
    <child
      link="RF_foot" />
    <axis
      xyz="0 0 0" />
  </joint>
</robot>